root - INFO - Бот запускается
telegram.ext.updater - INFO - Received signal 2 (SIGINT), stopping...
root - INFO - Бот запускается
telegram.ext.updater - INFO - Received signal 2 (SIGINT), stopping...
root - INFO - Bot is starting
telegram.ext.updater - INFO - Received signal 2 (SIGINT), stopping...
root - INFO - Бот запускается
telegram.ext.updater - INFO - Received signal 2 (SIGINT), stopping...
root - INFO - Bot is running
telegram.ext.updater - INFO - Received signal 2 (SIGINT), stopping...
root - INFO - Bot is running
telegram.ext.updater - INFO - Received signal 2 (SIGINT), stopping...
root - INFO - Бот запускается
telegram.ext.updater - INFO - Received signal 2 (SIGINT), stopping...
2019-05-29 18:54:06,533 - INFO - Bot is running
2019-05-29 18:55:23,867 - INFO - Received signal 2 (SIGINT), stopping...
2019-05-29 18:55:27,699 - INFO - Bot is running
2019-05-29 18:55:48,477 - INFO - О, привет!
2019-05-29 19:02:10,221 - INFO - Received signal 2 (SIGINT), stopping...
2019-05-29 19:02:16,981 - INFO - Bot is running
2019-05-29 19:02:33,711 - INFO - b'\xd0\x9e, \xd0\xbf\xd1\x80\xd0\xb8\xd0\xb2\xd0\xb5\xd1\x82!'
2019-05-29 19:02:33,711 - ERROR - An uncaught error was raised while processing the update
Traceback (most recent call last):
  File "C:\Users\Елена\AppData\Local\Programs\Python\Python36\lib\site-packages\telegram\ext\dispatcher.py", line 279, in process_update
    handler.handle_update(update, self)
  File "C:\Users\Елена\AppData\Local\Programs\Python\Python36\lib\site-packages\telegram\ext\commandhandler.py", line 173, in handle_update
    return self.callback(dispatcher.bot, update, **optional_args)
  File ".\bot.py", line 16, in greet_user
    update.message.reply_text(text)
  File "C:\Users\Елена\AppData\Local\Programs\Python\Python36\lib\site-packages\telegram\message.py", line 455, in reply_text
    return self.bot.send_message(self.chat_id, *args, **kwargs)
  File "C:\Users\Елена\AppData\Local\Programs\Python\Python36\lib\site-packages\telegram\bot.py", line 65, in decorator
    result = func(self, *args, **kwargs)
  File "C:\Users\Елена\AppData\Local\Programs\Python\Python36\lib\site-packages\telegram\bot.py", line 90, in decorator
    result = self._request.post(url, data, timeout=kwargs.get('timeout'))
  File "C:\Users\Елена\AppData\Local\Programs\Python\Python36\lib\site-packages\telegram\utils\request.py", line 308, in post
    body=json.dumps(data).encode('utf-8'),
  File "C:\Users\Елена\AppData\Local\Programs\Python\Python36\lib\json\__init__.py", line 231, in dumps
    return _default_encoder.encode(obj)
  File "C:\Users\Елена\AppData\Local\Programs\Python\Python36\lib\json\encoder.py", line 199, in encode
    chunks = self.iterencode(o, _one_shot=True)
  File "C:\Users\Елена\AppData\Local\Programs\Python\Python36\lib\json\encoder.py", line 257, in iterencode
    return _iterencode(o, 0)
  File "C:\Users\Елена\AppData\Local\Programs\Python\Python36\lib\json\encoder.py", line 180, in default
    o.__class__.__name__)
TypeError: Object of type 'bytes' is not JSON serializable
2019-05-29 19:03:27,107 - INFO - Received signal 2 (SIGINT), stopping...
2019-05-29 19:03:51,034 - INFO - Bot is running
2019-05-29 19:04:24,608 - INFO - b'\xd0\x9e, \xd0\xbf\xd1\x80\xd0\xb8\xd0\xb2\xd0\xb5\xd1\x82!'
2019-05-29 19:04:24,608 - ERROR - An uncaught error was raised while processing the update
Traceback (most recent call last):
  File "C:\Users\Елена\AppData\Local\Programs\Python\Python36\lib\site-packages\telegram\ext\dispatcher.py", line 279, in process_update
    handler.handle_update(update, self)
  File "C:\Users\Елена\AppData\Local\Programs\Python\Python36\lib\site-packages\telegram\ext\commandhandler.py", line 173, in handle_update
    return self.callback(dispatcher.bot, update, **optional_args)
  File ".\bot.py", line 16, in greet_user
    update.message.reply_text(text)
  File "C:\Users\Елена\AppData\Local\Programs\Python\Python36\lib\site-packages\telegram\message.py", line 455, in reply_text
    return self.bot.send_message(self.chat_id, *args, **kwargs)
  File "C:\Users\Елена\AppData\Local\Programs\Python\Python36\lib\site-packages\telegram\bot.py", line 65, in decorator
    result = func(self, *args, **kwargs)
  File "C:\Users\Елена\AppData\Local\Programs\Python\Python36\lib\site-packages\telegram\bot.py", line 90, in decorator
    result = self._request.post(url, data, timeout=kwargs.get('timeout'))
  File "C:\Users\Елена\AppData\Local\Programs\Python\Python36\lib\site-packages\telegram\utils\request.py", line 308, in post
    body=json.dumps(data).encode('utf-8'),
  File "C:\Users\Елена\AppData\Local\Programs\Python\Python36\lib\json\__init__.py", line 231, in dumps
    return _default_encoder.encode(obj)
  File "C:\Users\Елена\AppData\Local\Programs\Python\Python36\lib\json\encoder.py", line 199, in encode
    chunks = self.iterencode(o, _one_shot=True)
  File "C:\Users\Елена\AppData\Local\Programs\Python\Python36\lib\json\encoder.py", line 257, in iterencode
    return _iterencode(o, 0)
  File "C:\Users\Елена\AppData\Local\Programs\Python\Python36\lib\json\encoder.py", line 180, in default
    o.__class__.__name__)
TypeError: Object of type 'bytes' is not JSON serializable
2019-05-29 19:04:46,803 - INFO - Received signal 2 (SIGINT), stopping...
2019-05-29 19:04:54,891 - INFO - Bot is running
2019-05-29 19:05:05,687 - INFO - О, привет!
2019-05-29 19:12:01,916 - INFO - Received signal 2 (SIGINT), stopping...
2019-05-29 19:12:25,235 - INFO - Bot is running
2019-05-29 19:12:32,539 - INFO - О, привет!
2019-05-29 19:14:43,227 - INFO - Received signal 2 (SIGINT), stopping...
2019-05-29 19:14:47,895 - INFO - Bot is running
2019-05-29 19:14:54,388 - INFO - How are you?
2019-05-29 19:18:29,408 - INFO - Received signal 2 (SIGINT), stopping...
2019-05-29 19:26:50,791 - INFO - Bot is running
2019-05-29 19:28:08,158 - INFO - Received signal 2 (SIGINT), stopping...
2019-05-29 19:29:32,539 - INFO - Bot is running
2019-05-29 19:40:25,794 - INFO - Received signal 2 (SIGINT), stopping...
2019-05-29 19:40:33,003 - INFO - Bot is running
2019-05-29 19:40:57,555 - ERROR - An uncaught error was raised while processing the update
Traceback (most recent call last):
  File "C:\Users\Елена\AppData\Local\Programs\Python\Python36\lib\site-packages\telegram\ext\dispatcher.py", line 279, in process_update
    handler.handle_update(update, self)
  File "C:\Users\Елена\AppData\Local\Programs\Python\Python36\lib\site-packages\telegram\ext\messagehandler.py", line 169, in handle_update
    return self.callback(dispatcher.bot, update, **optional_args)
  File ".\bot.py", line 18, in talk_to_me
    user_text = f'Привет {update.message.chat.first_name}! Ты написал: {update.message.chat.text}'
AttributeError: 'Chat' object has no attribute 'text'
2019-05-29 19:41:32,289 - INFO - Received signal 2 (SIGINT), stopping...
2019-05-29 19:42:11,590 - INFO - Bot is running
2019-05-29 19:42:19,133 - ERROR - An uncaught error was raised while processing the update
Traceback (most recent call last):
  File "C:\Users\Елена\AppData\Local\Programs\Python\Python36\lib\site-packages\telegram\ext\dispatcher.py", line 279, in process_update
    handler.handle_update(update, self)
  File "C:\Users\Елена\AppData\Local\Programs\Python\Python36\lib\site-packages\telegram\ext\messagehandler.py", line 169, in handle_update
    return self.callback(dispatcher.bot, update, **optional_args)
  File ".\bot.py", line 18, in talk_to_me
    user_text = f'Привет {update.message.chat.first_name}! Ты написал: {update.message.chat.text}'
AttributeError: 'Chat' object has no attribute 'text'
2019-05-29 19:43:54,538 - INFO - Received signal 2 (SIGINT), stopping...
2019-05-29 19:44:01,908 - INFO - Bot is running
2019-05-29 19:44:08,669 - ERROR - An uncaught error was raised while processing the update
Traceback (most recent call last):
  File "C:\Users\Елена\AppData\Local\Programs\Python\Python36\lib\site-packages\telegram\ext\dispatcher.py", line 279, in process_update
    handler.handle_update(update, self)
  File "C:\Users\Елена\AppData\Local\Programs\Python\Python36\lib\site-packages\telegram\ext\messagehandler.py", line 169, in handle_update
    return self.callback(dispatcher.bot, update, **optional_args)
  File ".\bot.py", line 18, in talk_to_me
    user_text = 'Привет {}! Ты написал: {}'.format(update.message.chat.first_name, update.message.chat.text)
AttributeError: 'Chat' object has no attribute 'text'
2019-05-29 19:48:12,831 - INFO - Received signal 2 (SIGINT), stopping...
2019-05-29 19:48:16,501 - INFO - Bot is running
2019-05-29 19:49:41,748 - INFO - Received signal 2 (SIGINT), stopping...
2019-05-29 19:49:48,071 - INFO - Bot is running
2019-05-29 19:50:51,894 - INFO - Received signal 2 (SIGINT), stopping...
2019-05-29 19:51:05,008 - INFO - Bot is running
2019-05-29 19:52:56,438 - INFO - Received signal 2 (SIGINT), stopping...
2019-05-29 19:53:05,100 - INFO - Bot is running
2019-05-29 19:53:09,681 - ERROR - An uncaught error was raised while processing the update
Traceback (most recent call last):
  File "C:\Users\Елена\AppData\Local\Programs\Python\Python36\lib\site-packages\telegram\ext\dispatcher.py", line 279, in process_update
    handler.handle_update(update, self)
  File "C:\Users\Елена\AppData\Local\Programs\Python\Python36\lib\site-packages\telegram\ext\messagehandler.py", line 169, in handle_update
    return self.callback(dispatcher.bot, update, **optional_args)
  File ".\bot.py", line 19, in talk_to_me
    user_text = f'Привет {update.message.text.chat.first_name}'
AttributeError: 'str' object has no attribute 'chat'
2019-05-29 19:53:33,403 - INFO - Received signal 2 (SIGINT), stopping...
2019-05-29 19:53:44,398 - INFO - Bot is running
2019-05-29 19:53:58,895 - ERROR - An uncaught error was raised while processing the update
Traceback (most recent call last):
  File "C:\Users\Елена\AppData\Local\Programs\Python\Python36\lib\site-packages\telegram\ext\dispatcher.py", line 279, in process_update
    handler.handle_update(update, self)
  File "C:\Users\Елена\AppData\Local\Programs\Python\Python36\lib\site-packages\telegram\ext\messagehandler.py", line 169, in handle_update
    return self.callback(dispatcher.bot, update, **optional_args)
  File ".\bot.py", line 19, in talk_to_me
    user_text = f'Привет {update.message.text.chat}'
AttributeError: 'str' object has no attribute 'chat'
2019-05-29 19:54:12,478 - INFO - Received signal 2 (SIGINT), stopping...
2019-05-29 19:54:39,996 - INFO - Bot is running
2019-05-29 19:56:59,003 - INFO - Received signal 2 (SIGINT), stopping...
2019-05-29 19:57:06,874 - INFO - Bot is running
2019-05-29 19:58:37,907 - INFO - Received signal 2 (SIGINT), stopping...
2019-05-29 19:58:45,436 - INFO - Bot is running
2019-05-29 20:01:53,019 - INFO - Received signal 2 (SIGINT), stopping...
2019-05-29 20:02:05,219 - INFO - Bot is running
2019-05-29 20:13:03,234 - INFO - Received signal 2 (SIGINT), stopping...
2019-05-29 20:13:11,290 - INFO - Bot is running
2019-05-29 20:13:18,661 - ERROR - An uncaught error was raised while processing the update
Traceback (most recent call last):
  File "C:\Users\Елена\AppData\Local\Programs\Python\Python36\lib\site-packages\telegram\ext\dispatcher.py", line 279, in process_update
    handler.handle_update(update, self)
  File "C:\Users\Елена\AppData\Local\Programs\Python\Python36\lib\site-packages\telegram\ext\messagehandler.py", line 169, in handle_update
    return self.callback(dispatcher.bot, update, **optional_args)
  File ".\bot.py", line 19, in talk_to_me
    logging.info("User: %s, Chat id: %s, Message: %s", update.message.chat.firstname,
AttributeError: 'Chat' object has no attribute 'firstname'
2019-05-29 20:24:37,765 - INFO - Received signal 2 (SIGINT), stopping...
2019-05-29 20:24:41,260 - WARNING - Exiting immediately!
2019-05-29 20:24:45,345 - INFO - Bot is running
2019-05-29 20:25:00,794 - INFO - User: ElenaKorzinkina, Chat id: 320778871, Message: lol
2019-05-29 20:26:51,747 - INFO - Received signal 2 (SIGINT), stopping...
